

/*
	if exception is raise in try Block it can be only handle by 
	catch block and it can not be handled by the finally Block.
*/



class Finally2
{
	public static void main(String[] args) 
	{
		System.out.println("start");
		try
		{
			System.out.println("Inside try block");	
			System.out.println(10/0);
		}
		finally
			{
				System.out.println("Inside finally block");
			}
			System.out.println("Stop");
	}
}